Workbook
Name MPCalc1: [1]Internals!$D$4
Name MPCalc10: [1]Internals!$D$13
Name MPCalc11: [1]Internals!$D$14
Name MPCalc12: [1]Internals!$D$15
Name MPCalc2: [1]Internals!$D$5
Name MPCalc3: [1]Internals!$D$6
Name MPCalc4: [1]Internals!$D$7
Name MPCalc5: [1]Internals!$D$8
Name MPCalc6: [1]Internals!$D$9
Name MPCalc7: [1]Internals!$D$10
Name MPCalc8: [1]Internals!$D$11
Name MPCalc9: [1]Internals!$D$12

Sheet Master Sheet
C1: Deal Analyzer for Rentals
C4: Property Address: | D4: 1500 Hemphill St. Charlotte, NC 28208
C5: Date
C7: INPUTS
C8: Leverage: | D8: 0.75 | F8: Marginal Tax Bracket: | J8: 0.28
C9: Appreciation: | D9: 0.05 | F9: Capital Gains Rate: | J9: 0.28
C10: Interest Rate: | D10: 0.0525 | F10: Value of the Land: | J10: 0.1
C11: # of Units | D11: 10 | F11: Total Square Footage | J11: 8918
C12: Market Cap Rate | D12: 0.1 | F12: Cash on Cash Return 1st Year | J12: =J55/E27 -> 0.093398098
C13: COMPARATIVE ANALYSIS
C14: Price Per Square Foot | E14: =E22/J11 -> 44.853106
C15: Price Per Unit | E15: =E22/D11 -> 40000
C16: Gross Rent Multiplier | E16: =J40/E22 -> 0.15
C17: Net Income Multiplier | E17: =(1/D12) -> 10
C18: Cap Rate | E18: =J53/E22 -> 0.0966325
C19: Present Market Value | E19: =E17*J53 -> 386530 | F19: **Only Yellow numbers should be replaced in top section of the Analyzer. Yellow block should be filled in below as well.
C21: PURCHASE ANALYSIS
C22: Purchase Price | E22: 400000
C23: Closing Costs | D23: 0.01 | E23: =0.01*E22 -> 4000
C24: Total Cost | E24: =SUM(E22:E23) -> 404000
C25: First Mortgage | D25: =D8 -> 0.75 | E25: =E22*D8 -> 300000
C26: Second Mortgage
C27: Down Payment | E27: =(E24-E25) -> 104000
C29: FINANCING ANALYSIS
C30: Interest Rate (r ) | F30: =D10/12 -> 0.004375 | G30: Payments Left | H30: Year | I30: Closing Loan Balance | J30: Amortization
C31: Term in Months (n) | F31: 180 | G31: =F31-12 -> 168 | H31: 1 | I31: =PV($F$30,G31,$F$34) -> 286488.35 | J31: =$F$32-I31 -> 13511.647
C32: Amount Borrowed (PV) | F32: =E25 -> 300000 | G32: =$F$31-24 -> 156 | H32: 2 | I32: =PV($F$30,G32,$F$34) -> 272250.02 | J32: =I31-I32 -> 14238.329
C33: Balloon Payment (FV) | F33: 0 | G33: =$F$31-36 -> 144 | H33: 3 | I33: =PV($F$30,G33,$F$34) -> 257245.93 | J33: =I32-I33 -> 15004.093
C34: Monthly Payment (D) | F34: =PMT(F30,F31,F32,F33) -> -2411.6331 | G34: =$F$31-48 -> 132 | H34: 4 | I34: =PV($F$30,G34,$F$34) -> 241434.89 | J34: =I33-I34 -> 15811.041
G35: =$F$31-60 -> 120 | H35: 5 | I35: =PV($F$30,G35,$F$34) -> 224773.5 | J35: =I34-I35 -> 16661.389
H36: Total Pay Down | I36: =SUM(J31:J35) -> 75226.498
C37: FIRST YEAR OPERATING PROJECTION
C38: Income/Expense | F38: Based on | I38: Monthly | J38: Annual
C40: Gross Scheduled Income/Net Rents | I40: 5000 | J40: =I40*12 -> 60000
C41: Vacancies | E41: 0.08 | I41: =J41/12 -> 400 | J41: =J40*E41 -> 4800
C42: Legal | I42: =J42/12 -> 0 | J42: 0
C43: Advertising | I43: =J43/12 -> 0 | J43: 0
C44: Cleaning | I44: =J44/12 -> 0 | J44: 0
C45: Miscellaneous | I45: =J45/12 -> 0 | J45: 0
C46: Insurance | I46: =J46/12 -> 166.66667 | J46: 2000
...

Sheet Sheet3

Sheet Single DCF
A1: Future Sales Price
B3: Single DCF
A4: Periodic Rate | C4: 0.1
A5: No. of Periods | C5: 5
A6: Sales Price | B6: 2500000 | C6: =-PV(C4,C5,,B6) -> 1552303.3

Sheet DCF
A1: Discounted Cash Flow
A4: Periodic Rate | C4: 0.1
A5: DCF Year 1 | B5: ='Master Sheet'!F82 -> 9713.4022 | C5: =-PV($C$4,1,,B5) -> 8830.3657
A6: DCF Year 2 | B6: ='Master Sheet'!G82 -> 11178.092 | C6: =-PV($C$4,2,,B6) -> 9238.0928
A7: DCF Year 3 | B7: ='Master Sheet'!H82 -> 12687.549 | C7: =-PV($C$4,3,,B7) -> 9532.3435
A8: DCF Year 4 | B8: ='Master Sheet'!I82 -> 14243.124 | C8: =-PV($C$4,4,,B8) -> 9728.2455
A9: DCF Year 5 | B9: ='Master Sheet'!J82+'Master Sheet'!I97 -> 252965.08 | C9: =-PV($C$4,5,,B9) -> 157071.41
A10: DCF | B10: 0 | C10: =-PV($C$4,6,,B10) -> 0
A11: DCF | B11: 0 | C11: =-PV($C$4,7,,B11) -> 0
A12: DCF | B12: 0 | C12: =-PV($C$4,8,,B12) -> 0
A13: DCF | B13: 0 | C13: =-PV($C$4,9,,B13) -> 0
A14: DCF | B14: 0 | C14: =-PV($C$4,10,,B14) -> 0
A15: PV of Future Cash Flow | C15: =SUM(C5:C14) -> 194400.46
A16: TOTAL NPV | C16: =C15-'Master Sheet'!E27 -> 90400.461
A17: PROFITABILITY INDEX | C17: =C15/'Master Sheet'!E27 -> 1.8692352

Sheet Balloon Payment
A1: Interest Rate (r ) | D1: ='Master Sheet'!F30 -> 0.004375 | E1: Payments Left | F1: Year | G1: Closing Loan Balance | H1: Amortization
A2: Term in Months (n) | D2: ='Master Sheet'!F31 -> 180 | E2: ='Master Sheet'!G31 -> 168 | F2: 1 | G2: =PV($D$1,E2,$D$4,,0) -> 286488.35 | H2: ='Master Sheet'!J31 -> 13511.647
A3: Amount Borrowed (PV) | D3: ='Master Sheet'!F32 -> 300000 | E3: =E2-12 -> 156 | F3: 2 | G3: =PV($D$1,E3,$D$4,,0) -> 272250.02 | H3: =G2-G3 -> 14238.329
A4: Monthly Payment (D) | D4: ='Master Sheet'!F34 -> -2411.6331 | E4: =E3-12 -> 144 | F4: 3 | G4: =PV($D$1,E4,$D$4,,0) -> 257245.93 | H4: =G3-G4 -> 15004.093
E5: =E4-12 -> 132 | F5: 4 | G5: =PV($D$1,E5,$D$4,,0) -> 241434.89 | H5: =G4-G5 -> 15811.041
E6: =E5-12 -> 120 | F6: 5 | G6: =PV($D$1,E6,$D$4,,0) -> 224773.5 | H6: =G5-G6 -> 16661.389
E7: =E6-12 -> 108 | F7: 6 | G7: =PV($D$1,E7,$D$4,,0) -> 207216.03 | H7: =G6-G7 -> 17557.47
E8: =E7-12 -> 96 | F8: 7 | G8: =PV($D$1,E8,$D$4,,0) -> 188714.29 | H8: =G7-G8 -> 18501.744
E9: =E8-12 -> 84 | F9: 8 | G9: =PV($D$1,E9,$D$4,,0) -> 169217.49 | H9: =G8-G9 -> 19496.802
E10: =E9-12 -> 72 | F10: 9 | G10: =PV($D$1,E10,$D$4,,0) -> 148672.11 | H10: =G9-G10 -> 20545.377
E11: =E10-12 -> 60 | F11: 10 | G11: =PV($D$1,E11,$D$4,,0) -> 127021.76 | H11: =G10-G11 -> 21650.346
E12: =E11-12 -> 48 | F12: 11 | G12: =PV($D$1,E12,$D$4,,0) -> 104207.02 | H12: =G11-G12 -> 22814.743
E13: =E12-12 -> 36 | F13: 12 | G13: =PV($D$1,E13,$D$4,,0) -> 80165.258 | H13: =G12-G13 -> 24041.763
E14: =E13-12 -> 24 | F14: 13 | G14: =PV($D$1,E14,$D$4,,0) -> 54830.484 | H14: =G13-G14 -> 25334.774
E15: =E14-12 -> 12 | F15: 14 | G15: =PV($D$1,E15,$D$4,,0) -> 28133.158 | H15: =G14-G15 -> 26697.326
E16: =E15-12 -> 0 | F16: 15 | G16: =PV($D$1,E16,$D$4,,0) -> 0 | H16: =G15-G16 -> 28133.158
... E31: =E30-12 -> -180 | F31: 30 | G31: =PV($D$1,E31,$D$4,,0) -> -658236.85 | H31: =G30-G31 -> 61727.606
